<?xml version="1.0" ?>
<robot name="Robot">
  <!-- ===================== 基座与升降、双臂：保持不变 ===================== -->
  <!-- base_link -->
  <link name="base_link">
    <inertial>
      <origin xyz="-0.044044 4.1046E-05 0.35314" rpy="0 0 0"/>
      <mass value="62.34"/>
      <inertia ixx="2.4972" ixy="-5.136E-05" ixz="-0.026499" iyy="2.9084" iyz="-0.00014713" izz="1.479"/>
    </inertial>
    <visual>
      <origin xyz="0 0 0" rpy="0 0 0"/>
      <geometry>
        <mesh filename="TR4_torso_description/meshes/base_link.STL"/>
      </geometry>
      <material name=""><color rgba="0.89412 0.91373 0.92941 1"/></material>
    </visual>
    <collision>
      <origin xyz="0 0 0" rpy="0 0 0"/>
      <geometry>
        <mesh filename="TR4_torso_description/meshes/base_link.STL"/>
      </geometry>
    </collision>
  </link>

  <link name="torso">
    <inertial>
      <origin xyz="0.00027401 -0.14991 0.91143" rpy="0 0 0"/>
      <mass value="3.3193"/>
      <inertia ixx="0.016893" ixy="-1.2784E-05" ixz="-7.5907E-05" iyy="0.026595" iyz="-0.0010839" izz="0.018448"/>
    </inertial>
    <visual>
      <origin xyz="0 0 0" rpy="0 0 0"/>
      <geometry>
        <mesh filename="TR4_torso_description/meshes/torso.STL"/>
      </geometry>
      <material name=""><color rgba="0.43922 0.43922 0.43922 1"/></material>
    </visual>
    <collision>
      <origin xyz="0 0 0" rpy="0 0 0"/>
      <geometry>
        <mesh filename="TR4_torso_description/meshes/torso.STL"/>
      </geometry>
    </collision>
  </link>

  <!-- elevation joint -->
  <joint name="elevation" type="prismatic">
    <origin rpy="0 0 1.5708" xyz="-0.11205 -0.00063586 0.39566"/>
    <parent link="base_link"/>
    <child link="torso"/>
    <axis xyz="0 0 1"/>
    <limit effort="0" lower="0" upper="0" velocity="0"/>
  </joint>

  <!-- Base Link -->
  <link name="left_arm_base_link">
    <inertial>
      <origin rpy="0 0 0" xyz="-0.000433277303987328 -3.54664423471128E-05 0.0599427668933796"/>
      <mass value="0.841070778135659"/>
      <inertia ixx="0.0017261110801622" ixy="2.52746264980217E-06" ixz="-3.67690303614961E-05" iyy="0.00170987405835604" iyz="1.67996364994424E-06" izz="0.000904023422915791"/>
    </inertial>
    <visual>
      <origin rpy="0 0 0" xyz="0 0 0"/>
      <geometry>
        <mesh filename="rm_65_b_description/meshes/base_link.STL"/>
      </geometry>
      <material name="">
        <color rgba="1 1 1 1"/>
      </material>
    </visual>
    <collision>
      <origin rpy="0 0 0" xyz="0 0 0"/>
      <geometry>
        <mesh filename="rm_65_b_description/meshes/base_link.STL"/>
      </geometry>
    </collision>
  </link>
  <joint name="left_arm_mount_joint" type="fixed">
    <parent link="torso"/>
    <child link="left_arm_base_link"/>
    <origin rpy="-3.137776 -1.570000 -0.004613" xyz="0.025635 -0.158686 0.942540"/>
  </joint>
  <!-- Link1 -->
  <link name="left_arm_Link1">
    <inertial>
      <origin rpy="0 0 0" xyz="1.2226305431569E-08 0.0211079974844683 -0.0251854220842269"/>
      <mass value="0.593563443690403"/>
      <inertia ixx="0.00126614120341847" ixy="-1.294980943835E-08" ixz="-9.80120923066996E-09" iyy="0.00118168178300364" iyz="-0.00021121727444415" izz="0.00056135241627747"/>
    </inertial>
    <visual>
      <origin rpy="0 0 0" xyz="0 0 0"/>
      <geometry>
        <mesh filename="rm_65_b_description/meshes/link1.STL"/>
      </geometry>
      <material name="">
        <color rgba="1 1 1 1"/>
      </material>
    </visual>
    <collision>
      <origin rpy="0 0 0" xyz="0 0 0"/>
      <geometry>
        <mesh filename="rm_65_b_description/meshes/link1.STL"/>
      </geometry>
    </collision>
  </link>
  <!-- Joint1 -->
  <joint name="left_arm_joint1" type="revolute">
    <origin rpy="0 0 0" xyz="0 0 0.2405"/>
    <parent link="left_arm_base_link"/>
    <child link="left_arm_Link1"/>
    <axis xyz="0 0 1"/>
    <limit effort="60" lower="-3.1" upper="3.1" velocity="3.14"/>
  </joint>
  <!-- Link2 -->
  <link name="left_arm_Link2">
    <inertial>
      <origin rpy="0 0 0" xyz="0.152256463426163 4.75383656106654E-07 -0.00620260383607792"/>
      <mass value="0.864175046869043"/>
      <inertia ixx="0.00089150298478414" ixy="-2.23268489334765E-08" ixz="0.00156246461035015" iyy="0.00733754343083901" iyz="6.28110889329165E-09" izz="0.00697869103915473"/>
    </inertial>
    <visual>
      <origin rpy="0 0 0" xyz="0 0 0"/>
      <geometry>
        <mesh filename="rm_65_b_description/meshes/link2.STL"/>
      </geometry>
      <material name="">
        <color rgba="1 1 1 1"/>
      </material>
    </visual>
    <collision>
      <origin rpy="0 0 0" xyz="0 0 0"/>
      <geometry>
        <mesh filename="rm_65_b_description/meshes/link2.STL"/>
      </geometry>
    </collision>
  </link>
  <!-- Joint2 -->
  <joint name="left_arm_joint2" type="revolute">
    <origin rpy="1.5708 -1.5708 0" xyz="0 0 0"/>
    <parent link="left_arm_Link1"/>
    <child link="left_arm_Link2"/>
    <axis xyz="0 0 1"/>
    <limit effort="60" lower="-2.268" upper="2.268" velocity="3.14"/>
  </joint>
  <!-- Link3 -->
  <link name="left_arm_Link3">
    <inertial>
      <origin rpy="0 0 0" xyz="5.05312670989961E-06 -0.0595925663694732 0.010569069212336"/>
      <mass value="0.289633681624654"/>
      <inertia ixx="0.00063737100450158" ixy="-7.05261293649751E-08" ixz="-3.86643272239426E-08" iyy="0.00015648388095025" iyz="-0.00014461035994916" izz="0.000614178164773085"/>
    </inertial>
    <visual>
      <origin rpy="0 0 0" xyz="0 0 0"/>
      <geometry>
        <mesh filename="rm_65_b_description/meshes/link3.STL"/>
      </geometry>
      <material name="">
        <color rgba="1 1 1 1"/>
      </material>
    </visual>
    <collision>
      <origin rpy="0 0 0" xyz="0 0 0"/>
      <geometry>
        <mesh filename="rm_65_b_description/meshes/link3.STL"/>
      </geometry>
    </collision>
  </link>
  <!-- Joint3 -->
  <joint name="left_arm_joint3" type="revolute">
    <origin rpy="0 0 1.5708" xyz="0.256 0 0"/>
    <parent link="left_arm_Link2"/>
    <child link="left_arm_Link3"/>
    <axis xyz="0 0 1"/>
    <limit effort="30" lower="-2.355" upper="2.355" velocity="3.92"/>
  </joint>
  <!-- Link4 -->
  <link name="left_arm_Link4">
    <inertial>
      <origin rpy="0 0 0" xyz="1.15516617405898E-06 -0.0180424468598241 -0.0215394748352687"/>
      <mass value="0.239419768320061"/>
      <inertia ixx="0.000285938919722783" ixy="3.07101359163101E-09" ixz="-2.21994118981953E-09" iyy="0.000262727540304212" iyz="4.4236583260078E-05" izz="0.000119888082791859"/>
    </inertial>
    <visual>
      <origin rpy="0 0 0" xyz="0 0 0"/>
      <geometry>
        <mesh filename="rm_65_b_description/meshes/link4.STL"/>
      </geometry>
      <material name="">
        <color rgba="1 1 1 1"/>
      </material>
    </visual>
    <collision>
      <origin rpy="0 0 0" xyz="0 0 0"/>
      <geometry>
        <mesh filename="rm_65_b_description/meshes/link4.STL"/>
      </geometry>
    </collision>
  </link>
  <!-- Joint4 -->
  <joint name="left_arm_joint4" type="revolute">
    <origin rpy="1.5708 0 0" xyz="0 -0.21 0"/>
    <parent link="left_arm_Link3"/>
    <child link="left_arm_Link4"/>
    <axis xyz="0 0 1"/>
    <limit effort="10" lower="-3.1" upper="3.1" velocity="3.92"/>
  </joint>
  <!-- Link5 -->
  <link name="left_arm_Link5">
    <inertial>
      <origin rpy="0 0 0" xyz="3.19794786262152E-06 -0.0593808368101458 0.00736804250989326"/>
      <mass value="0.218799761431678"/>
      <inertia ixx="0.000350540363914072" ixy="-3.41781619975602E-08" ixz="-1.77056457224373E-08" iyy="0.000104927867487581" iyz="-7.82431228461971E-05" izz="0.000334482418423629"/>
    </inertial>
    <visual>
      <origin rpy="0 0 0" xyz="0 0 0"/>
      <geometry>
        <mesh filename="rm_65_b_description/meshes/link5.STL"/>
      </geometry>
      <material name="">
        <color rgba="1 1 1 1"/>
      </material>
    </visual>
    <collision>
      <origin rpy="0 0 0" xyz="0 0 0"/>
      <geometry>
        <mesh filename="rm_65_b_description/meshes/link5.STL"/>
      </geometry>
    </collision>
  </link>
  <!-- Joint5 -->
  <joint name="left_arm_joint5" type="revolute">
    <origin rpy="-1.5708 0 0" xyz="0 0 0"/>
    <parent link="left_arm_Link4"/>
    <child link="left_arm_Link5"/>
    <axis xyz="0 0 1"/>
    <limit effort="10" lower="-2.233" upper="2.233" velocity="3.92"/>
  </joint>
  <!-- Link6 -->
  <link name="left_arm_Link6">
    <inertial>
      <origin rpy="0 0 0" xyz="0.000714234511756999 -0.000396718732824521 -0.0126723660946126"/>
      <mass value="0.0649018034311231"/>
      <inertia ixx="2.02766547502765E-05" ixy="-1.32505200276849E-06" ixz="-2.5845091522508E-08" iyy="1.87986725225022E-05" iyz="3.39471452125439E-09" izz="3.17885459163081E-05"/>
    </inertial>
    <visual>
      <origin rpy="0 0 0" xyz="0 0 0"/>
      <geometry>
        <mesh filename="rm_65_b_description/meshes/link6.STL"/>
      </geometry>
      <material name="">
        <color rgba="1 1 1 1"/>
      </material>
    </visual>
    <collision>
      <origin rpy="0 0 0" xyz="0 0 0"/>
      <geometry>
        <mesh filename="rm_65_b_description/meshes/link6.STL"/>
      </geometry>
    </collision>
  </link>
  <!-- Joint6 -->
  <joint name="left_arm_joint6" type="revolute">
    <origin rpy="1.5708 0 0" xyz="0 -0.144 0"/>
    <parent link="left_arm_Link5"/>
    <child link="left_arm_Link6"/>
    <axis xyz="0 0 1"/>
    <limit effort="10" lower="-6.28" upper="6.28" velocity="3.92"/>
  </joint>
  <joint name="left_gripper_eef_joint" type="fixed">
    <parent link="left_arm_Link6"/>
    <child link="left_gripper_base_link"/>
    <origin rpy="0 -1.5708 0" xyz="0 0 0"/>
  </joint>

  <!-- Base Link -->
  <link name="right_arm_base_link">
    <inertial>
      <origin rpy="0 0 0" xyz="-0.000433277303987328 -3.54664423471128E-05 0.0599427668933796"/>
      <mass value="0.841070778135659"/>
      <inertia ixx="0.0017261110801622" ixy="2.52746264980217E-06" ixz="-3.67690303614961E-05" iyy="0.00170987405835604" iyz="1.67996364994424E-06" izz="0.000904023422915791"/>
    </inertial>
    <visual>
      <origin rpy="0 0 0" xyz="0 0 0"/>
      <geometry>
        <mesh filename="rm_65_b_description/meshes/base_link.STL"/>
      </geometry>
      <material name="">
        <color rgba="1 1 1 1"/>
      </material>
    </visual>
    <collision>
      <origin rpy="0 0 0" xyz="0 0 0"/>
      <geometry>
        <mesh filename="rm_65_b_description/meshes/base_link.STL"/>
      </geometry>
    </collision>
  </link>
  <joint name="right_arm_mount_joint" type="fixed">
    <parent link="torso"/>
    <child link="right_arm_base_link"/>
    <origin rpy="-2.036165 -1.569019 2.035368" xyz="-0.025635 -0.158686 0.942540"/>
  </joint>
  <!-- Link1 -->
  <link name="right_arm_Link1">
    <inertial>
      <origin rpy="0 0 0" xyz="1.2226305431569E-08 0.0211079974844683 -0.0251854220842269"/>
      <mass value="0.593563443690403"/>
      <inertia ixx="0.00126614120341847" ixy="-1.294980943835E-08" ixz="-9.80120923066996E-09" iyy="0.00118168178300364" iyz="-0.00021121727444415" izz="0.00056135241627747"/>
    </inertial>
    <visual>
      <origin rpy="0 0 0" xyz="0 0 0"/>
      <geometry>
        <mesh filename="rm_65_b_description/meshes/link1.STL"/>
      </geometry>
      <material name="">
        <color rgba="1 1 1 1"/>
      </material>
    </visual>
    <collision>
      <origin rpy="0 0 0" xyz="0 0 0"/>
      <geometry>
        <mesh filename="rm_65_b_description/meshes/link1.STL"/>
      </geometry>
    </collision>
  </link>
  <!-- Joint1 -->
  <joint name="right_arm_joint1" type="revolute">
    <origin rpy="0 0 0" xyz="0 0 0.2405"/>
    <parent link="right_arm_base_link"/>
    <child link="right_arm_Link1"/>
    <axis xyz="0 0 1"/>
    <limit effort="60" lower="-3.1" upper="3.1" velocity="3.14"/>
  </joint>
  <!-- Link2 -->
  <link name="right_arm_Link2">
    <inertial>
      <origin rpy="0 0 0" xyz="0.152256463426163 4.75383656106654E-07 -0.00620260383607792"/>
      <mass value="0.864175046869043"/>
      <inertia ixx="0.00089150298478414" ixy="-2.23268489334765E-08" ixz="0.00156246461035015" iyy="0.00733754343083901" iyz="6.28110889329165E-09" izz="0.00697869103915473"/>
    </inertial>
    <visual>
      <origin rpy="0 0 0" xyz="0 0 0"/>
      <geometry>
        <mesh filename="rm_65_b_description/meshes/link2.STL"/>
      </geometry>
      <material name="">
        <color rgba="1 1 1 1"/>
      </material>
    </visual>
    <collision>
      <origin rpy="0 0 0" xyz="0 0 0"/>
      <geometry>
        <mesh filename="rm_65_b_description/meshes/link2.STL"/>
      </geometry>
    </collision>
  </link>
  <!-- Joint2 -->
  <joint name="right_arm_joint2" type="revolute">
    <origin rpy="1.5708 -1.5708 0" xyz="0 0 0"/>
    <parent link="right_arm_Link1"/>
    <child link="right_arm_Link2"/>
    <axis xyz="0 0 1"/>
    <limit effort="60" lower="-2.268" upper="2.268" velocity="3.14"/>
  </joint>
  <!-- Link3 -->
  <link name="right_arm_Link3">
    <inertial>
      <origin rpy="0 0 0" xyz="5.05312670989961E-06 -0.0595925663694732 0.010569069212336"/>
      <mass value="0.289633681624654"/>
      <inertia ixx="0.00063737100450158" ixy="-7.05261293649751E-08" ixz="-3.86643272239426E-08" iyy="0.00015648388095025" iyz="-0.00014461035994916" izz="0.000614178164773085"/>
    </inertial>
    <visual>
      <origin rpy="0 0 0" xyz="0 0 0"/>
      <geometry>
        <mesh filename="rm_65_b_description/meshes/link3.STL"/>
      </geometry>
      <material name="">
        <color rgba="1 1 1 1"/>
      </material>
    </visual>
    <collision>
      <origin rpy="0 0 0" xyz="0 0 0"/>
      <geometry>
        <mesh filename="rm_65_b_description/meshes/link3.STL"/>
      </geometry>
    </collision>
  </link>
  <!-- Joint3 -->
  <joint name="right_arm_joint3" type="revolute">
    <origin rpy="0 0 1.5708" xyz="0.256 0 0"/>
    <parent link="right_arm_Link2"/>
    <child link="right_arm_Link3"/>
    <axis xyz="0 0 1"/>
    <limit effort="30" lower="-2.355" upper="2.355" velocity="3.92"/>
  </joint>
  <!-- Link4 -->
  <link name="right_arm_Link4">
    <inertial>
      <origin rpy="0 0 0" xyz="1.15516617405898E-06 -0.0180424468598241 -0.0215394748352687"/>
      <mass value="0.239419768320061"/>
      <inertia ixx="0.000285938919722783" ixy="3.07101359163101E-09" ixz="-2.21994118981953E-09" iyy="0.000262727540304212" iyz="4.4236583260078E-05" izz="0.000119888082791859"/>
    </inertial>
    <visual>
      <origin rpy="0 0 0" xyz="0 0 0"/>
      <geometry>
        <mesh filename="rm_65_b_description/meshes/link4.STL"/>
      </geometry>
      <material name="">
        <color rgba="1 1 1 1"/>
      </material>
    </visual>
    <collision>
      <origin rpy="0 0 0" xyz="0 0 0"/>
      <geometry>
        <mesh filename="rm_65_b_description/meshes/link4.STL"/>
      </geometry>
    </collision>
  </link>
  <!-- Joint4 -->
  <joint name="right_arm_joint4" type="revolute">
    <origin rpy="1.5708 0 0" xyz="0 -0.21 0"/>
    <parent link="right_arm_Link3"/>
    <child link="right_arm_Link4"/>
    <axis xyz="0 0 1"/>
    <limit effort="10" lower="-3.1" upper="3.1" velocity="3.92"/>
  </joint>
  <!-- Link5 -->
  <link name="right_arm_Link5">
    <inertial>
      <origin rpy="0 0 0" xyz="3.19794786262152E-06 -0.0593808368101458 0.00736804250989326"/>
      <mass value="0.218799761431678"/>
      <inertia ixx="0.000350540363914072" ixy="-3.41781619975602E-08" ixz="-1.77056457224373E-08" iyy="0.000104927867487581" iyz="-7.82431228461971E-05" izz="0.000334482418423629"/>
    </inertial>
    <visual>
      <origin rpy="0 0 0" xyz="0 0 0"/>
      <geometry>
        <mesh filename="rm_65_b_description/meshes/link5.STL"/>
      </geometry>
      <material name="">
        <color rgba="1 1 1 1"/>
      </material>
    </visual>
    <collision>
      <origin rpy="0 0 0" xyz="0 0 0"/>
      <geometry>
        <mesh filename="rm_65_b_description/meshes/link5.STL"/>
      </geometry>
    </collision>
  </link>
  <!-- Joint5 -->
  <joint name="right_arm_joint5" type="revolute">
    <origin rpy="-1.5708 0 0" xyz="0 0 0"/>
    <parent link="right_arm_Link4"/>
    <child link="right_arm_Link5"/>
    <axis xyz="0 0 1"/>
    <limit effort="10" lower="-2.233" upper="2.233" velocity="3.92"/>
  </joint>
  <!-- Link6 -->
  <link name="right_arm_Link6">
    <inertial>
      <origin rpy="0 0 0" xyz="0.000714234511756999 -0.000396718732824521 -0.0126723660946126"/>
      <mass value="0.0649018034311231"/>
      <inertia ixx="2.02766547502765E-05" ixy="-1.32505200276849E-06" ixz="-2.5845091522508E-08" iyy="1.87986725225022E-05" iyz="3.39471452125439E-09" izz="3.17885459163081E-05"/>
    </inertial>
    <visual>
      <origin rpy="0 0 0" xyz="0 0 0"/>
      <geometry>
        <mesh filename="rm_65_b_description/meshes/link6.STL"/>
      </geometry>
      <material name="">
        <color rgba="1 1 1 1"/>
      </material>
    </visual>
    <collision>
      <origin rpy="0 0 0" xyz="0 0 0"/>
      <geometry>
        <mesh filename="rm_65_b_description/meshes/link6.STL"/>
      </geometry>
    </collision>
  </link>
  <!-- Joint6 -->
  <joint name="right_arm_joint6" type="revolute">
    <origin rpy="1.5708 0 0" xyz="0 -0.144 0"/>
    <parent link="right_arm_Link5"/>
    <child link="right_arm_Link6"/>
    <axis xyz="0 0 1"/>
    <limit effort="10" lower="-6.28" upper="6.28" velocity="3.92"/>
  </joint>
  <joint name="right_gripper_eef_joint" type="fixed">
    <parent link="right_arm_Link6"/>
    <child link="right_gripper_base_link"/>
    <origin rpy="0 -1.5708 0" xyz="0 0 0"/>
  </joint>

  <link name="left_gripper_base_link">
    <inertial>
      <origin xyz="0.041595 3.8229E-05 0.0084072" rpy="0 0 0"/>
      <mass value="0.21079"/>
      <inertia ixx="0.00015248" ixy="-4.2673E-07" ixz="-1.2221E-06" iyy="0.0001472" iyz="-7.0428E-07" izz="0.00015973"/>
    </inertial>
    <visual>
      <origin xyz="0 0 0" rpy="0 0 0"/>
      <geometry>
        <mesh filename="TR4_gripper_description/meshes/base_link.STL"/>
      </geometry>
      <material name=""><color rgba="0.89804 0.91765 0.92941 1"/></material>
    </visual>
    <collision>
      <origin xyz="0 0 0" rpy="0 0 0"/>
      <geometry>
        <mesh filename="TR4_gripper_description/meshes/base_link.STL"/>
      </geometry>
    </collision>
  </link>

  <link name="left_gripper_l_link1">
    <inertial>
      <origin xyz="0.025591 0.01098 0.00012619" rpy="0 0 0"/>
      <mass value="0.025052"/>
      <inertia ixx="3.8147E-06" ixy="8.0164E-07" ixz="-2.625E-08" iyy="4.5288E-06" iyz="1.6433E-08" izz="6.104E-06"/>
    </inertial>
    <visual>
      <origin xyz="0 0 0" rpy="0 0 0"/>
      <geometry>
        <mesh filename="TR4_gripper_description/meshes/l_link1.STL"/>
      </geometry>
      <material name=""><color rgba="0.11373 0.11373 0.11373 1"/></material>
    </visual>
    <collision>
      <origin xyz="0 0 0" rpy="0 0 0"/>
      <geometry>
        <mesh filename="TR4_gripper_description/meshes/l_link1.STL"/>
      </geometry>
    </collision>
  </link>

  <joint name="left_gripper_l_joint1" type="revolute">
    <origin xyz="0.096753 0.0306 0" rpy="0 0 0"/>
    <parent link="left_gripper_base_link"/>
    <child link="left_gripper_l_link1"/>
    <axis xyz="0 0 -1"/>
    <limit lower="-1.0472" upper="0" effort="0" velocity="0"/>
  </joint>

  <link name="left_gripper_l_link2">
    <inertial>
      <origin xyz="0.017854 -0.014801 0.00022853" rpy="0 0 0"/>
      <mass value="0.016248"/>
      <inertia ixx="1.1526E-06" ixy="3.4183E-07" ixz="6.0475E-09" iyy="1.8417E-06" iyz="-1.7073E-08" izz="1.9483E-06"/>
    </inertial>
    <visual>
      <origin xyz="0 0 0" rpy="0 0 0"/>
      <geometry>
        <mesh filename="TR4_gripper_description/meshes/l_link2.STL"/>
      </geometry>
      <material name=""><color rgba="0.1098 0.1098 0.1098 1"/></material>
    </visual>
    <collision>
      <origin xyz="0 0 0" rpy="0 0 0"/>
      <geometry>
        <mesh filename="TR4_gripper_description/meshes/l_link2.STL"/>
      </geometry>
    </collision>
  </link>

  <joint name="left_gripper_l_joint2" type="fixed">
    <origin xyz="0.056957 -0.0046989 0" rpy="0 0 0"/>
    <parent link="left_gripper_l_link1"/>
    <child link="left_gripper_l_link2"/>
  </joint>

  <link name="left_gripper_l_link3">
    <inertial>
      <origin xyz="-0.026661 0.0026672 -6.7314E-05" rpy="0 0 0"/>
      <mass value="0.012807"/>
      <inertia ixx="3.0944E-06" ixy="2.1726E-07" ixz="-6.4057E-09" iyy="5.8728E-06" iyz="1.2515E-10" izz="3.0853E-06"/>
    </inertial>
    <visual>
      <origin xyz="0 0 0" rpy="0 0 0"/>
      <geometry>
        <mesh filename="TR4_gripper_description/meshes/l_link3.STL"/>
      </geometry>
      <material name=""><color rgba="0.11373 0.11373 0.11373 1"/></material>
    </visual>
    <collision>
      <origin xyz="0 0 0" rpy="0 0 0"/>
      <geometry>
        <mesh filename="TR4_gripper_description/meshes/l_link3.STL"/>
      </geometry>
    </collision>
  </link>

  <joint name="left_gripper_l_joint3" type="revolute">
    <origin xyz="0.0065155 -0.017901 0" rpy="0 0 0"/>
    <parent link="left_gripper_l_link2"/>
    <child link="left_gripper_l_link3"/>
    <axis xyz="0 0 -1"/>
    <limit lower="-1.0472" upper="0" effort="0" velocity="0"/>
  </joint>

  <link name="left_gripper_r_link1">
    <inertial>
      <origin xyz="0.025591 -0.01098 0.00012554" rpy="0 0 0"/>
      <mass value="0.025051"/>
      <inertia ixx="3.8145E-06" ixy="-8.0156E-07" ixz="-2.639E-08" iyy="4.5285E-06" iyz="-1.6541E-08" izz="6.1038E-06"/>
    </inertial>
    <visual>
      <origin xyz="0 0 0" rpy="0 0 0"/>
      <geometry>
        <mesh filename="TR4_gripper_description/meshes/r_link1.STL"/>
      </geometry>
      <material name=""><color rgba="0.11373 0.11373 0.11373 1"/></material>
    </visual>
    <collision>
      <origin xyz="0 0 0" rpy="0 0 0"/>
      <geometry>
        <mesh filename="TR4_gripper_description/meshes/r_link1.STL"/>
      </geometry>
    </collision>
  </link>

  <joint name="left_gripper_r_joint1" type="revolute">
    <origin xyz="0.096753 -0.0306 0" rpy="0 0 0"/>
    <parent link="left_gripper_base_link"/>
    <child link="left_gripper_r_link1"/>
    <axis xyz="0 0 -1"/>
    <limit lower="0" upper="1.0472" effort="0" velocity="0"/>
  </joint>

  <link name="left_gripper_r_link2">
    <inertial>
      <origin xyz="0.017856 0.014802 0.00022741" rpy="0 0 0"/>
      <mass value="0.016244"/>
      <inertia ixx="1.1523E-06" ixy="-3.4181E-07" ixz="6.1573E-09" iyy="1.8414E-06" iyz="1.71E-08" izz="1.9481E-06"/>
    </inertial>
    <visual>
      <origin xyz="0 0 0" rpy="0 0 0"/>
      <geometry>
        <mesh filename="TR4_gripper_description/meshes/r_link2.STL"/>
      </geometry>
      <material name=""><color rgba="0.054902 0.054902 0.054902 1"/></material>
    </visual>
    <collision>
      <origin xyz="0 0 0" rpy="0 0 0"/>
      <geometry>
        <mesh filename="TR4_gripper_description/meshes/r_link2.STL"/>
      </geometry>
    </collision>
  </link>

  <joint name="left_gripper_r_joint2" type="fixed">
    <origin xyz="0.056957 0.0046989 0" rpy="0 0 0"/>
    <parent link="left_gripper_r_link1"/>
    <child link="left_gripper_r_link2"/>
  </joint>

  <link name="left_gripper_r_link3">
    <inertial>
      <origin xyz="-0.02666 -0.0026673 -6.7319E-05" rpy="0 0 0"/>
      <mass value="0.012807"/>
      <inertia ixx="3.0944E-06" ixy="-2.1728E-07" ixz="-6.4065E-09" iyy="5.8728E-06" iyz="-1.2491E-10" izz="3.0853E-06"/>
    </inertial>
    <visual>
      <origin xyz="0 0 0" rpy="0 0 0"/>
      <geometry>
        <mesh filename="TR4_gripper_description/meshes/r_link3.STL"/>
      </geometry>
      <material name=""><color rgba="0.11373 0.11373 0.11373 1"/></material>
    </visual>
    <collision>
      <origin xyz="0 0 0" rpy="0 0 0"/>
      <geometry>
        <mesh filename="TR4_gripper_description/meshes/r_link3.STL"/>
      </geometry>
    </collision>
  </link>

  <joint name="left_gripper_r_joint3" type="revolute">
    <origin xyz="0.0065147 0.017901 0" rpy="0 0 0"/>
    <parent link="left_gripper_r_link2"/>
    <child link="left_gripper_r_link3"/>
    <axis xyz="0 0 -1"/>
    <limit lower="0" upper="1.0472" effort="0" velocity="0"/>
  </joint>

  <!-- ================================================================== -->
  <!-- =============== 右侧 zc_gripper_rev3（带前缀 right_） ============== -->
  <link name="right_gripper_base_link">
    <inertial>
      <origin xyz="0.041595 3.8229E-05 0.0084072" rpy="0 0 0"/>
      <mass value="0.21079"/>
      <inertia ixx="0.00015248" ixy="-4.2673E-07" ixz="-1.2221E-06" iyy="0.0001472" iyz="-7.0428E-07" izz="0.00015973"/>
    </inertial>
    <visual>
      <origin xyz="0 0 0" rpy="0 0 0"/>
      <geometry>
        <mesh filename="TR4_gripper_description/meshes/base_link.STL"/>
      </geometry>
      <material name=""><color rgba="0.89804 0.91765 0.92941 1"/></material>
    </visual>
    <collision>
      <origin xyz="0 0 0" rpy="0 0 0"/>
      <geometry>
        <mesh filename="TR4_gripper_description/meshes/base_link.STL"/>
      </geometry>
    </collision>
  </link>

  <link name="right_gripper_l_link1">
    <inertial>
      <origin xyz="0.025591 0.01098 0.00012619" rpy="0 0 0"/>
      <mass value="0.025052"/>
      <inertia ixx="3.8147E-06" ixy="8.0164E-07" ixz="-2.625E-08" iyy="4.5288E-06" iyz="1.6433E-08" izz="6.104E-06"/>
    </inertial>
    <visual>
      <origin xyz="0 0 0" rpy="0 0 0"/>
      <geometry>
        <mesh filename="TR4_gripper_description/meshes/l_link1.STL"/>
      </geometry>
      <material name=""><color rgba="0.11373 0.11373 0.11373 1"/></material>
    </visual>
    <collision>
      <origin xyz="0 0 0" rpy="0 0 0"/>
      <geometry>
        <mesh filename="TR4_gripper_description/meshes/l_link1.STL"/>
      </geometry>
    </collision>
  </link>

  <joint name="right_gripper_l_joint1" type="revolute">
    <origin xyz="0.096753 0.0306 0" rpy="0 0 0"/>
    <parent link="right_gripper_base_link"/>
    <child link="right_gripper_l_link1"/>
    <axis xyz="0 0 -1"/>
    <limit lower="-1.0472" upper="0" effort="0" velocity="0"/>
  </joint>

  <link name="right_gripper_l_link2">
    <inertial>
      <origin xyz="0.017854 -0.014801 0.00022853" rpy="0 0 0"/>
      <mass value="0.016248"/>
      <inertia ixx="1.1526E-06" ixy="3.4183E-07" ixz="6.0475E-09" iyy="1.8417E-06" iyz="-1.7073E-08" izz="1.9483E-06"/>
    </inertial>
    <visual>
      <origin xyz="0 0 0" rpy="0 0 0"/>
      <geometry>
        <mesh filename="TR4_gripper_description/meshes/l_link2.STL"/>
      </geometry>
      <material name=""><color rgba="0.1098 0.1098 0.1098 1"/></material>
    </visual>
    <collision>
      <origin xyz="0 0 0" rpy="0 0 0"/>
      <geometry>
        <mesh filename="TR4_gripper_description/meshes/l_link2.STL"/>
      </geometry>
    </collision>
  </link>

  <joint name="right_gripper_l_joint2" type="fixed">
    <origin xyz="0.056957 -0.0046989 0" rpy="0 0 0"/>
    <parent link="right_gripper_l_link1"/>
    <child link="right_gripper_l_link2"/>
  </joint>


  <link name="right_gripper_l_link3">
    <inertial>
      <origin xyz="-0.026661 0.0026672 -6.7314E-05" rpy="0 0 0"/>
      <mass value="0.012807"/>
      <inertia ixx="3.0944E-06" ixy="2.1726E-07" ixz="-6.4057E-09" iyy="5.8728E-06" iyz="1.2515E-10" izz="3.0853E-06"/>
    </inertial>
    <visual>
      <origin xyz="0 0 0" rpy="0 0 0"/>
      <geometry>
        <mesh filename="TR4_gripper_description/meshes/l_link3.STL"/>
      </geometry>
      <material name=""><color rgba="0.11373 0.11373 0.11373 1"/></material>
    </visual>
    <collision>
      <origin xyz="0 0 0" rpy="0 0 0"/>
      <geometry>
        <mesh filename="TR4_gripper_description/meshes/l_link3.STL"/>
      </geometry>
    </collision>
  </link>

  <joint name="right_gripper_l_joint3" type="revolute">
    <origin xyz="0.0065155 -0.017901 0" rpy="0 0 0"/>
    <parent link="right_gripper_l_link2"/>
    <child link="right_gripper_l_link3"/>
    <axis xyz="0 0 -1"/>
    <limit lower="-1.0472" upper="0" effort="0" velocity="0"/>
  </joint>

  <link name="right_gripper_r_link1">
    <inertial>
      <origin xyz="0.025591 -0.01098 0.00012554" rpy="0 0 0"/>
      <mass value="0.025051"/>
      <inertia ixx="3.8145E-06" ixy="-8.0156E-07" ixz="-2.639E-08" iyy="4.5285E-06" iyz="-1.6541E-08" izz="6.1038E-06"/>
    </inertial>
    <visual>
      <origin xyz="0 0 0" rpy="0 0 0"/>
      <geometry>
        <mesh filename="TR4_gripper_description/meshes/r_link1.STL"/>
      </geometry>
      <material name=""><color rgba="0.11373 0.11373 0.11373 1"/></material>
    </visual>
    <collision>
      <origin xyz="0 0 0" rpy="0 0 0"/>
      <geometry>
        <mesh filename="TR4_gripper_description/meshes/r_link1.STL"/>
      </geometry>
    </collision>
  </link>

  <joint name="right_gripper_r_joint1" type="revolute">
    <origin xyz="0.096753 -0.0306 0" rpy="0 0 0"/>
    <parent link="right_gripper_base_link"/>
    <child link="right_gripper_r_link1"/>
    <axis xyz="0 0 -1"/>
    <limit lower="0" upper="1.0472" effort="0" velocity="0"/>
  </joint>

  <link name="right_gripper_r_link2">
    <inertial>
      <origin xyz="0.017856 0.014802 0.00022741" rpy="0 0 0"/>
      <mass value="0.016244"/>
      <inertia ixx="1.1523E-06" ixy="-3.4181E-07" ixz="6.1573E-09" iyy="1.8414E-06" iyz="1.71E-08" izz="1.9481E-06"/>
    </inertial>
    <visual>
      <origin xyz="0 0 0" rpy="0 0 0"/>
      <geometry>
        <mesh filename="TR4_gripper_description/meshes/r_link2.STL"/>
      </geometry>
      <material name=""><color rgba="0.054902 0.054902 0.054902 1"/></material>
    </visual>
    <collision>
      <origin xyz="0 0 0" rpy="0 0 0"/>
      <geometry>
        <mesh filename="TR4_gripper_description/meshes/r_link2.STL"/>
      </geometry>
    </collision>
  </link>

  <joint name="right_gripper_r_joint2" type="fixed">
    <origin xyz="0.056957 0.0046989 0" rpy="0 0 0"/>
    <parent link="right_gripper_r_link1"/>
    <child link="right_gripper_r_link2"/>
  </joint>

  <link name="right_gripper_r_link3">
    <inertial>
      <origin xyz="-0.02666 -0.0026673 -6.7319E-05" rpy="0 0 0"/>
      <mass value="0.012807"/>
      <inertia ixx="3.0944E-06" ixy="-2.1728E-07" ixz="-6.4065E-09" iyy="5.8728E-06" iyz="-1.2491E-10" izz="3.0853E-06"/>
    </inertial>
    <visual>
      <origin xyz="0 0 0" rpy="0 0 0"/>
      <geometry>
        <mesh filename="TR4_gripper_description/meshes/r_link3.STL"/>
      </geometry>
      <material name=""><color rgba="0.11373 0.11373 0.11373 1"/></material>
    </visual>
    <collision>
      <origin xyz="0 0 0" rpy="0 0 0"/>
      <geometry>
        <mesh filename="TR4_gripper_description/meshes/r_link3.STL"/>
      </geometry>
    </collision>
  </link>

  <joint name="right_gripper_r_joint3" type="revolute">
    <origin xyz="0.0065147 0.017901 0" rpy="0 0 0"/>
    <parent link="right_gripper_r_link2"/>
    <child link="right_gripper_r_link3"/>
    <axis xyz="0 0 -1"/>
    <limit lower="0" upper="1.0472" effort="0" velocity="0"/>
  </joint>
</robot>
